Workbook

Sheet Line finding
A1: Wavelength (nm) | B1: Wavelength (m) | C1: Line name | D1: Function to fit | E1: To fit (1/0) | F1: Fit priority (1 is first) | G1: Max position shift (m) | H1: Max line fwhm (m) | I1: Max influence radius (m) | J1: Linked variables
A2: 651.3964 | B2: =A2*0.000000001 -> 6.513964e-07 | D2: VoigtApparatus | E2: 0 | G2: 9e-12 | H2: 1.25e-10 | I2: 2e-10
A3: 651.5275 | B3: =A3*0.000000001 -> 6.515275e-07 | D3: VoigtApparatus | E3: 0 | G3: 9e-12 | H3: 1.25e-10 | I3: 2e-10
A4: 651.7227 | B4: =A4*0.000000001 -> 6.517227e-07 | D4: VoigtApparatus | E4: 0 | G4: 9e-12 | H4: 1.25e-10 | I4: 2e-10
A5: 651.7299 | B5: =A5*0.000000001 -> 6.517299e-07 | D5: VoigtApparatus | E5: 1 | G5: 9e-12 | H5: 1.25e-10 | I5: 2e-10
A6: 651.8366 | B6: =A6*0.000000001 -> 6.518366e-07 | D6: VoigtApparatus | E6: 0 | G6: 9e-12 | H6: 1.25e-10 | I6: 2e-10
A7: 651.983 | B7: =A7*0.000000001 -> 6.51983e-07 | C7: Mo1 | D7: VoigtApparatus | E7: 1 | G7: 9e-12 | H7: 1.25e-10 | I7: 3e-10 | J7: $apparatus = 0.0467081e-9; $Mo1_width_var = $apparatus + (1.25e-10 - $apparatus) / 2 * sin(~1.5); shape = $Mo1_width_var
A8: 652.1485 | B8: =A8*0.000000001 -> 6.521485e-07 | D8: VoigtApparatus | E8: 0 | G8: 9e-12 | H8: 1.25e-10 | I8: 2e-10
A9: 652.1831 | B9: =A9*0.000000001 -> 6.521831e-07 | D9: VoigtApparatus | E9: 0 | G9: 9e-12 | H9: 1.25e-10 | I9: 2e-10
A10: 652.3042 | B10: =A10*0.000000001 -> 6.523042e-07 | D10: VoigtApparatus | E10: 0 | G10: 9e-12 | H10: 1.25e-10 | I10: 2e-10
A11: 652.3605 | B11: =A11*0.000000001 -> 6.523605e-07 | D11: VoigtApparatus | E11: 0 | G11: 9e-12 | H11: 1.25e-10 | I11: 2e-10
A12: 652.6048 | B12: =A12*0.000000001 -> 6.526048e-07 | D12: VoigtApparatus | E12: 0 | G12: 9e-12 | H12: 1.25e-10 | I12: 2e-10
A13: 652.644 | B13: =A13*0.000000001 -> 6.52644e-07 | D13: VoigtApparatus | E13: 0 | G13: 9e-12 | H13: 1.25e-10 | I13: 2e-10
A14: 652.6804 | B14: =A14*0.000000001 -> 6.526804e-07 | D14: VoigtApparatus | E14: 0 | G14: 9e-12 | H14: 1.25e-10 | I14: 2e-10
A15: 652.7371 | B15: =A15*0.000000001 -> 6.527371e-07 | D15: VoigtApparatus | E15: 0 | G15: 9e-12 | H15: 1.25e-10 | I15: 2e-10
A16: 652.9631 | B16: =A16*0.000000001 -> 6.529631e-07 | D16: VoigtApparatus | E16: 0 | G16: 9e-12 | H16: 1.25e-10 | I16: 2e-10
A17: 653.171 | B17: =A17*0.000000001 -> 6.53171e-07 | D17: VoigtApparatus | E17: 0 | G17: 9e-12 | H17: 1.25e-10 | I17: 2e-10
A18: 653.238 | B18: =A18*0.000000001 -> 6.53238e-07 | C18: W1 | D18: VoigtApparatus | E18: 1 | G18: 9e-12 | H18: 1.25e-10 | I18: 3e-10 | J18: $W1_width_var = $apparatus + (1.25e-10 - $apparatus) / 2 * sin(~1.5); shape = $W1_width_var
A19: 653.3549 | B19: =A19*0.000000001 -> 6.533549e-07 | D19: VoigtApparatus | E19: 0 | G19: 9e-12 | H19: 1.25e-10 | I19: 2e-10
A20: 653.3972 | B20: =A20*0.000000001 -> 6.533972e-07 | D20: VoigtApparatus | E20: 0 | G20: 9e-12 | H20: 1.25e-10 | I20: 2e-10
A21: 653.5087 | B21: =A21*0.000000001 -> 6.535087e-07 | D21: VoigtApparatus | E21: 0 | G21: 9e-12 | H21: 1.25e-10 | I21: 2e-10
A22: 653.643 | B22: =A22*0.000000001 -> 6.53643e-07 | D22: VoigtApparatus | E22: 0 | G22: 9e-12 | H22: 1.25e-10 | I22: 2e-10
A23: 653.6509 | B23: =A23*0.000000001 -> 6.536509e-07 | D23: VoigtApparatus | E23: 0 | G23: 9e-12 | H23: 1.25e-10 | I23: 2e-10
A24: 653.7628 | B24: =A24*0.000000001 -> 6.537628e-07 | D24: VoigtApparatus | E24: 0 | G24: 9e-12 | H24: 1.25e-10 | I24: 2e-10
A25: 653.83 | B25: =A25*0.000000001 -> 6.5383e-07 | D25: VoigtApparatus | E25: 1 | G25: 9e-12 | H25: 1.25e-10 | I25: 2e-10
A26: 653.9689 | B26: =A26*0.000000001 -> 6.539689e-07 | D26: VoigtApparatus | E26: 0 | G26: 9e-12 | H26: 1.25e-10 | I26: 2e-10
A27: 654.0552 | B27: =A27*0.000000001 -> 6.540552e-07 | D27: VoigtApparatus | E27: 0 | G27: 9e-12 | H27: 1.25e-10 | I27: 2e-10
A28: 654.1273 | B28: =A28*0.000000001 -> 6.541273e-07 | D28: VoigtApparatus | E28: 0 | G28: 9e-12 | H28: 1.25e-10 | I28: 2e-10
A29: 654.1309 | B29: =A29*0.000000001 -> 6.541309e-07 | D29: VoigtApparatus | E29: 0 | G29: 9e-12 | H29: 1.25e-10 | I29: 2e-10
A30: 654.3188 | B30: =A30*0.000000001 -> 6.543188e-07 | D30: VoigtApparatus | E30: 0 | G30: 9e-12 | H30: 1.25e-10 | I30: 2e-10
... A32: 654.4678 | B32: =A32*0.000000001 -> 6.544678e-07 | D32: VoigtApparatus | E32: 0 | G32: 9e-12 | H32: 1.25e-10 | I32: 2e-10
A33: 654.4719 | B33: =A33*0.000000001 -> 6.544719e-07 | C33: Mo_unknown | D33: VoigtApparatus | E33: 1 | G33: 9e-12 | H33: 1.25e-10 | I33: 2e-10 | J33: shape = $Mo1_width_var
A34: 654.6537 | B34: =A34*0.000000001 -> 6.546537e-07 | D34: VoigtApparatus | E34: 0 | G34: 9e-12 | H34: 1.25e-10 | I34: 2e-10
A35: 654.7883 | B35: =A35*0.000000001 -> 6.547883e-07 | D35: VoigtApparatus | E35: 0 | G35: 9e-12 | H35: 1.25e-10 | I35: 2e-10
A36: 654.8856 | B36: =A36*0.000000001 -> 6.548856e-07 | D36: VoigtApparatus | E36: 0 | G36: 9e-12 | H36: 1.25e-10 | I36: 2e-10
A37: 654.9534 | B37: =A37*0.000000001 -> 6.549534e-07 | D37: VoigtApparatus | E37: 1 | G37: 9e-12 | H37: 1.25e-10 | I37: 2e-10
A38: 655.0911 | B38: =A38*0.000000001 -> 6.550911e-07 | D38: VoigtApparatus | E38: 0 | G38: 9e-12 | H38: 1.25e-10 | I38: 2e-10
A39: 655.2848 | B39: =A39*0.000000001 -> 6.552848e-07 | D39: VoigtApparatus | E39: 0 | G39: 9e-12 | H39: 1.25e-10 | I39: 2e-10
A40: 655.345 | B40: =A40*0.000000001 -> 6.55345e-07 | C40: Mo_unknown | D40: VoigtApparatus | E40: 1 | G40: 9e-12 | H40: 1.25e-10 | I40: 2e-10 | J40: shape = $Mo1_width_var
A41: 655.3997 | B41: =A41*0.000000001 -> 6.553997e-07 | D41: VoigtApparatus | E41: 1 | G41: 9e-12 | H41: 1.25e-10 | I41: 2e-10
...

Sheet Output
A1: Wavelength (m) | B1: Identificator | C1: Function to fit | D1: To fit (1/0) | E1: Fit priority (1 is first) | F1: Max position shift (m) | G1: Max line fwhm (m) | H1: Max influence radius (m) | I1: Linked variables
A2: =IF('Line finding'!$B2="","",'Line finding'!B2) -> 6.513964e-07 | B2: =IF('Line finding'!$B2="","",IF(ISBLANK('Line finding'!C2),"",'Line finding'!C2)) | C2: =IF('Line finding'!$B2="","",IF(ISBLANK('Line finding'!D2),"",'Line finding'!D2)) -> VoigtApparatus | D2: =IF('Line finding'!$B2="","",IF(ISBLANK('Line finding'!E2),"",'Line finding'!E2)) -> 0 | E2: =IF('Line finding'!$B2="","",IF(ISBLANK('Line finding'!F2),"",'Line finding'!F2)) | F2: =IF('Line finding'!$B2="","",IF(ISBLANK('Line finding'!G2),"",'Line finding'!G2)) -> 9e-12 | G2: =IF('Line finding'!$B2="","",IF(ISBLANK('Line finding'!H2),"",'Line finding'!H2)) -> 1.25e-10 | H2: =IF('Line finding'!$B2="","",IF(ISBLANK('Line finding'!I2),"",'Line finding'!I2)) -> 2e-10 | I2: =IF('Line finding'!$B2="","",IF(ISBLANK('Line finding'!J2),"",'Line finding'!J2))
A3: =IF('Line finding'!$B3="","",'Line finding'!B3) -> 6.515275e-07 | B3: =IF('Line finding'!$B3="","",IF(ISBLANK('Line finding'!C3),"",'Line finding'!C3)) | C3: =IF('Line finding'!$B3="","",IF(ISBLANK('Line finding'!D3),"",'Line finding'!D3)) -> VoigtApparatus | D3: =IF('Line finding'!$B3="","",IF(ISBLANK('Line finding'!E3),"",'Line finding'!E3)) -> 0 | E3: =IF('Line finding'!$B3="","",IF(ISBLANK('Line finding'!F3),"",'Line finding'!F3)) | F3: =IF('Line finding'!$B3="","",IF(ISBLANK('Line finding'!G3),"",'Line finding'!G3)) -> 9e-12 | G3: =IF('Line finding'!$B3="","",IF(ISBLANK('Line finding'!H3),"",'Line finding'!H3)) -> 1.25e-10 | H3: =IF('Line finding'!$B3="","",IF(ISBLANK('Line finding'!I3),"",'Line finding'!I3)) -> 2e-10 | I3: =IF('Line finding'!$B3="","",IF(ISBLANK('Line finding'!J3),"",'Line finding'!J3))
A4: =IF('Line finding'!$B4="","",'Line finding'!B4) -> 6.517227e-07 | B4: =IF('Line finding'!$B4="","",IF(ISBLANK('Line finding'!C4),"",'Line finding'!C4)) | C4: =IF('Line finding'!$B4="","",IF(ISBLANK('Line finding'!D4),"",'Line finding'!D4)) -> VoigtApparatus | D4: =IF('Line finding'!$B4="","",IF(ISBLANK('Line finding'!E4),"",'Line finding'!E4)) -> 0 | E4: =IF('Line finding'!$B4="","",IF(ISBLANK('Line finding'!F4),"",'Line finding'!F4)) | F4: =IF('Line finding'!$B4="","",IF(ISBLANK('Line finding'!G4),"",'Line finding'!G4)) -> 9e-12 | G4: =IF('Line finding'!$B4="","",IF(ISBLANK('Line finding'!H4),"",'Line finding'!H4)) -> 1.25e-10 | H4: =IF('Line finding'!$B4="","",IF(ISBLANK('Line finding'!I4),"",'Line finding'!I4)) -> 2e-10 | I4: =IF('Line finding'!$B4="","",IF(ISBLANK('Line finding'!J4),"",'Line finding'!J4))
A5: =IF('Line finding'!$B5="","",'Line finding'!B5) -> 6.517299e-07 | B5: =IF('Line finding'!$B5="","",IF(ISBLANK('Line finding'!C5),"",'Line finding'!C5)) | C5: =IF('Line finding'!$B5="","",IF(ISBLANK('Line finding'!D5),"",'Line finding'!D5)) -> VoigtApparatus | D5: =IF('Line finding'!$B5="","",IF(ISBLANK('Line finding'!E5),"",'Line finding'!E5)) -> 1 | E5: =IF('Line finding'!$B5="","",IF(ISBLANK('Line finding'!F5),"",'Line finding'!F5)) | F5: =IF('Line finding'!$B5="","",IF(ISBLANK('Line finding'!G5),"",'Line finding'!G5)) -> 9e-12 | G5: =IF('Line finding'!$B5="","",IF(ISBLANK('Line finding'!H5),"",'Line finding'!H5)) -> 1.25e-10 | H5: =IF('Line finding'!$B5="","",IF(ISBLANK('Line finding'!I5),"",'Line finding'!I5)) -> 2e-10 | I5: =IF('Line finding'!$B5="","",IF(ISBLANK('Line finding'!J5),"",'Line finding'!J5))
A6: =IF('Line finding'!$B6="","",'Line finding'!B6) -> 6.518366e-07 | B6: =IF('Line finding'!$B6="","",IF(ISBLANK('Line finding'!C6),"",'Line finding'!C6)) | C6: =IF('Line finding'!$B6="","",IF(ISBLANK('Line finding'!D6),"",'Line finding'!D6)) -> VoigtApparatus | D6: =IF('Line finding'!$B6="","",IF(ISBLANK('Line finding'!E6),"",'Line finding'!E6)) -> 0 | E6: =IF('Line finding'!$B6="","",IF(ISBLANK('Line finding'!F6),"",'Line finding'!F6)) | F6: =IF('Line finding'!$B6="","",IF(ISBLANK('Line finding'!G6),"",'Line finding'!G6)) -> 9e-12 | G6: =IF('Line finding'!$B6="","",IF(ISBLANK('Line finding'!H6),"",'Line finding'!H6)) -> 1.25e-10 | H6: =IF('Line finding'!$B6="","",IF(ISBLANK('Line finding'!I6),"",'Line finding'!I6)) -> 2e-10 | I6: =IF('Line finding'!$B6="","",IF(ISBLANK('Line finding'!J6),"",'Line finding'!J6))
A7: =IF('Line finding'!$B7="","",'Line finding'!B7) -> 6.51983e-07 | B7: =IF('Line finding'!$B7="","",IF(ISBLANK('Line finding'!C7),"",'Line finding'!C7)) -> Mo1 | C7: =IF('Line finding'!$B7="","",IF(ISBLANK('Line finding'!D7),"",'Line finding'!D7)) -> VoigtApparatus | D7: =IF('Line finding'!$B7="","",IF(ISBLANK('Line finding'!E7),"",'Line finding'!E7)) -> 1 | E7: =IF('Line finding'!$B7="","",IF(ISBLANK('Line finding'!F7),"",'Line finding'!F7)) | F7: =IF('Line finding'!$B7="","",IF(ISBLANK('Line finding'!G7),"",'Line finding'!G7)) -> 9e-12 | G7: =IF('Line finding'!$B7="","",IF(ISBLANK('Line finding'!H7),"",'Line finding'!H7)) -> 1.25e-10 | H7: =IF('Line finding'!$B7="","",IF(ISBLANK('Line finding'!I7),"",'Line finding'!I7)) -> 3e-10 | I7: =IF('Line finding'!$B7="","",IF(ISBLANK('Line finding'!J7),"",'Line finding'!J7)) -> $apparatus = 0.0467081e-9; $Mo1_width_var = $apparatus + (1.25e-10 - $apparatus) / 2 * sin(~1.5); shape = $Mo1_width_var
A8: =IF('Line finding'!$B8="","",'Line finding'!B8) -> 6.521485e-07 | B8: =IF('Line finding'!$B8="","",IF(ISBLANK('Line finding'!C8),"",'Line finding'!C8)) | C8: =IF('Line finding'!$B8="","",IF(ISBLANK('Line finding'!D8),"",'Line finding'!D8)) -> VoigtApparatus | D8: =IF('Line finding'!$B8="","",IF(ISBLANK('Line finding'!E8),"",'Line finding'!E8)) -> 0 | E8: =IF('Line finding'!$B8="","",IF(ISBLANK('Line finding'!F8),"",'Line finding'!F8)) | F8: =IF('Line finding'!$B8="","",IF(ISBLANK('Line finding'!G8),"",'Line finding'!G8)) -> 9e-12 | G8: =IF('Line finding'!$B8="","",IF(ISBLANK('Line finding'!H8),"",'Line finding'!H8)) -> 1.25e-10 | H8: =IF('Line finding'!$B8="","",IF(ISBLANK('Line finding'!I8),"",'Line finding'!I8)) -> 2e-10 | I8: =IF('Line finding'!$B8="","",IF(ISBLANK('Line finding'!J8),"",'Line finding'!J8))
A9: =IF('Line finding'!$B9="","",'Line finding'!B9) -> 6.521831e-07 | B9: =IF('Line finding'!$B9="","",IF(ISBLANK('Line finding'!C9),"",'Line finding'!C9)) | C9: =IF('Line finding'!$B9="","",IF(ISBLANK('Line finding'!D9),"",'Line finding'!D9)) -> VoigtApparatus | D9: =IF('Line finding'!$B9="","",IF(ISBLANK('Line finding'!E9),"",'Line finding'!E9)) -> 0 | E9: =IF('Line finding'!$B9="","",IF(ISBLANK('Line finding'!F9),"",'Line finding'!F9)) | F9: =IF('Line finding'!$B9="","",IF(ISBLANK('Line finding'!G9),"",'Line finding'!G9)) -> 9e-12 | G9: =IF('Line finding'!$B9="","",IF(ISBLANK('Line finding'!H9),"",'Line finding'!H9)) -> 1.25e-10 | H9: =IF('Line finding'!$B9="","",IF(ISBLANK('Line finding'!I9),"",'Line finding'!I9)) -> 2e-10 | I9: =IF('Line finding'!$B9="","",IF(ISBLANK('Line finding'!J9),"",'Line finding'!J9))
A10: =IF('Line finding'!$B10="","",'Line finding'!B10) -> 6.523042e-07 | B10: =IF('Line finding'!$B10="","",IF(ISBLANK('Line finding'!C10),"",'Line finding'!C10)) | C10: =IF('Line finding'!$B10="","",IF(ISBLANK('Line finding'!D10),"",'Line finding'!D10)) -> VoigtApparatus | D10: =IF('Line finding'!$B10="","",IF(ISBLANK('Line finding'!E10),"",'Line finding'!E10)) -> 0 | E10: =IF('Line finding'!$B10="","",IF(ISBLANK('Line finding'!F10),"",'Line finding'!F10)) | F10: =IF('Line finding'!$B10="","",IF(ISBLANK('Line finding'!G10),"",'Line finding'!G10)) -> 9e-12 | G10: =IF('Line finding'!$B10="","",IF(ISBLANK('Line finding'!H10),"",'Line finding'!H10)) -> 1.25e-10 | H10: =IF('Line finding'!$B10="","",IF(ISBLANK('Line finding'!I10),"",'Line finding'!I10)) -> 2e-10 | I10: =IF('Line finding'!$B10="","",IF(ISBLANK('Line finding'!J10),"",'Line finding'!J10))
A11: =IF('Line finding'!$B11="","",'Line finding'!B11) -> 6.523605e-07 | B11: =IF('Line finding'!$B11="","",IF(ISBLANK('Line finding'!C11),"",'Line finding'!C11)) | C11: =IF('Line finding'!$B11="","",IF(ISBLANK('Line finding'!D11),"",'Line finding'!D11)) -> VoigtApparatus | D11: =IF('Line finding'!$B11="","",IF(ISBLANK('Line finding'!E11),"",'Line finding'!E11)) -> 0 | E11: =IF('Line finding'!$B11="","",IF(ISBLANK('Line finding'!F11),"",'Line finding'!F11)) | F11: =IF('Line finding'!$B11="","",IF(ISBLANK('Line finding'!G11),"",'Line finding'!G11)) -> 9e-12 | G11: =IF('Line finding'!$B11="","",IF(ISBLANK('Line finding'!H11),"",'Line finding'!H11)) -> 1.25e-10 | H11: =IF('Line finding'!$B11="","",IF(ISBLANK('Line finding'!I11),"",'Line finding'!I11)) -> 2e-10 | I11: =IF('Line finding'!$B11="","",IF(ISBLANK('Line finding'!J11),"",'Line finding'!J11))
A12: =IF('Line finding'!$B12="","",'Line finding'!B12) -> 6.526048e-07 | B12: =IF('Line finding'!$B12="","",IF(ISBLANK('Line finding'!C12),"",'Line finding'!C12)) | C12: =IF('Line finding'!$B12="","",IF(ISBLANK('Line finding'!D12),"",'Line finding'!D12)) -> VoigtApparatus | D12: =IF('Line finding'!$B12="","",IF(ISBLANK('Line finding'!E12),"",'Line finding'!E12)) -> 0 | E12: =IF('Line finding'!$B12="","",IF(ISBLANK('Line finding'!F12),"",'Line finding'!F12)) | F12: =IF('Line finding'!$B12="","",IF(ISBLANK('Line finding'!G12),"",'Line finding'!G12)) -> 9e-12 | G12: =IF('Line finding'!$B12="","",IF(ISBLANK('Line finding'!H12),"",'Line finding'!H12)) -> 1.25e-10 | H12: =IF('Line finding'!$B12="","",IF(ISBLANK('Line finding'!I12),"",'Line finding'!I12)) -> 2e-10 | I12: =IF('Line finding'!$B12="","",IF(ISBLANK('Line finding'!J12),"",'Line finding'!J12))
A13: =IF('Line finding'!$B13="","",'Line finding'!B13) -> 6.52644e-07 | B13: =IF('Line finding'!$B13="","",IF(ISBLANK('Line finding'!C13),"",'Line finding'!C13)) | C13: =IF('Line finding'!$B13="","",IF(ISBLANK('Line finding'!D13),"",'Line finding'!D13)) -> VoigtApparatus | D13: =IF('Line finding'!$B13="","",IF(ISBLANK('Line finding'!E13),"",'Line finding'!E13)) -> 0 | E13: =IF('Line finding'!$B13="","",IF(ISBLANK('Line finding'!F13),"",'Line finding'!F13)) | F13: =IF('Line finding'!$B13="","",IF(ISBLANK('Line finding'!G13),"",'Line finding'!G13)) -> 9e-12 | G13: =IF('Line finding'!$B13="","",IF(ISBLANK('Line finding'!H13),"",'Line finding'!H13)) -> 1.25e-10 | H13: =IF('Line finding'!$B13="","",IF(ISBLANK('Line finding'!I13),"",'Line finding'!I13)) -> 2e-10 | I13: =IF('Line finding'!$B13="","",IF(ISBLANK('Line finding'!J13),"",'Line finding'!J13))
... A99: =IF('Line finding'!$B99="","",'Line finding'!B99) | B99: =IF('Line finding'!$B99="","",IF(ISBLANK('Line finding'!C99),"",'Line finding'!C99)) | C99: =IF('Line finding'!$B99="","",IF(ISBLANK('Line finding'!D99),"",'Line finding'!D99)) | D99: =IF('Line finding'!$B99="","",IF(ISBLANK('Line finding'!E99),"",'Line finding'!E99)) | E99: =IF('Line finding'!$B99="","",IF(ISBLANK('Line finding'!F99),"",'Line finding'!F99)) | F99: =IF('Line finding'!$B99="","",IF(ISBLANK('Line finding'!G99),"",'Line finding'!G99)) | G99: =IF('Line finding'!$B99="","",IF(ISBLANK('Line finding'!H99),"",'Line finding'!H99)) | H99: =IF('Line finding'!$B99="","",IF(ISBLANK('Line finding'!I99),"",'Line finding'!I99)) | I99: =IF('Line finding'!$B99="","",IF(ISBLANK('Line finding'!J99),"",'Line finding'!J99))
